Workbook

Sheet Sheet1
A1: abbreviation | B1: FirstName | C1: MiddleName | D1: LastName | E1: Gender | F1: DOB | G1: RegisterNo | H1: Class | I1: admission Year | J1: Address | K1: Pincode | L1: Locality
A2: Mr. | B2: Adhav | C2: Chandrakant | D2: Nanasaheb | E2: Male | F2: 20215 | G2: 142 | H2: P.D. Arts | I2: 1975 | J2: Shivaji Road Kopargaon | K2: 423601 | L2: KOPARGAON
A3: Mr. | B3: Bharad | C3: Ananda | D3: Waman | E3: Male | F3: 19876 | G3: 80 | H3: B.Sc. | I3: 1975 | J3: Kopargaon | K3: 423601 | L3: KOPARGAON
A4: Mr. | B4: Shelke | C4: Ashok | D4: Bhikaji | E4: Male | F4: 20262 | G4: 80 | H4: B.Sc. | I4: 1975 | J4: Kopargaon | K4: 423601 | L4: KOPARGAON
A5: Mr. | B5: Tadage | C5: Anna | D5: Sopan | E5: Male | F5: 19876 | G5: 80 | H5: B.Sc. | I5: 1975 | J5: Kopargaon | K5: 423601 | L5: KOPARGAON
A6: Mr. | B6: Adhav | C6: Dinkar | D6: Nivrutti | E6: Male | F6: 20654 | G6: 80 | H6: B.Sc. | I6: 1975 | J6: Kopargaon | K6: 423601 | L6: KOPARGAON
A7: Mr. | B7: Ahire | C7: Gajendra | D7: Sadashiv | E7: Male | F7: 20348 | G7: 80 | H7: B.Sc. | I7: 1975 | J7: Kopargaon | K7: 423601 | L7: KOPARGAON
A8: Mr. | B8: Bhavrao | C8: Bhausaheb | D8: Pralhad | E8: Male | F8: 19931 | G8: 80 | H8: B.Sc. | I8: 1975 | J8: Kopargaon | K8: 423601 | L8: KOPARGAON
A9: Mr. | B9: Bhakare | C9: Vishwanath | D9: Bhimaji | E9: Male | F9: 19511 | G9: 80 | H9: B.Sc. | I9: 1975 | J9: Kopargaon | K9: 423601 | L9: KOPARGAON
A10: Mr. | B10: Bodhe | C10: Sakha | D10: Anantrao | E10: Male | F10: 23886 | G10: 80 | H10: B.Sc. | I10: 1975 | J10: Kopargaon | K10: 423601 | L10: KOPARGAON
A11: Mr. | B11: Chaudhari | C11: Deelip | D11: Baburao | E11: Male | F11: 20359 | G11: 81 | H11: B.Sc. | I11: 1975 | J11: Kopargaon | K11: 423601 | L11: KOPARGAON
A12: Mr. | B12: Dighe | C12: Punja | D12: Mahadu | E12: Male | F12: 19876 | G12: 81 | H12: B.Sc. | I12: 1975 | J12: Kopargaon | K12: 423601 | L12: KOPARGAON
A13: Mr. | B13: Dodiya | C13: Kumar | D13: Govindrao | E13: Male | F13: 19769 | G13: 81 | H13: B.Sc. | I13: 1975 | J13: Kopargaon | K13: 423601 | L13: KOPARGAON
... A28: Mr. | B28: Karwar | C28: Kashinath | D28: Sakharam | E28: Male | F28: 20090 | G28: 82 | H28: B.Sc. | I28: 1975 | J28: Kopargaon | K28: 423601 | L28: KOPARGAON

Sheet Sheet2
A1: Village Name | B1: Locality Name | C1: Pincode
A2: Kopargaon | B2: KOPARGAON | C2: 423601
A3: Pohegaon | B3: POHEGAON BK. | C3: 423605
A4: Madhi | B4: MADHI BK | C4: 423601
A5: Sinnar | B5: SINNAR | C5: 422103
A6: Jamkhed | B6: JAMKHED | C6: 413201
A7: Niphad | B7: NIPHAD | C7: 422303
A8: Newasa | B8: NEWASA | C8: 414603
A9: Shirdi | B9: SHIRDI | C9: 423109
A10: Kelwad | B10: SONAPAR | C10: 441501
A11: Wakadi | B11: WAKADI | C11: 413719
A12: Yeola | B12: YEVLA | C12: 423401
A13: Savargaon | B13: SAVARGAON | C13: 423401
... A20: Kolpewadi | B20: KOLPEWADI | C20: 423602
B21: MAHEGAON DESHMUKH | C21: 423602
B22: NANDGAON | C22: 415107

Sheet Sheet3
A2: Miss. | B2: Joshi | C2: Nanda | D2: Sitaram | E2: Female | F2: 21-101958 | G2: 163 | H2: P.D. Commerce | I2: 1975 | J2: Kopargaon | K2: =VLOOKUP(J2, Sheet2!A:C, 3, FALSE) -> 423601 | L2: =VLOOKUP(J2, Sheet2!A:C, 2, FALSE) -> KOPARGAON
A3: Mr. | B3: Joshi | C3: Sham | D3: Digambar | E3: Male | F3: 21200 | G3: 164 | H3: P.D. Commerce | I3: 1975 | J3: Pohegaon | K3: =VLOOKUP(J3, Sheet2!A:C, 3, FALSE) -> 423605 | L3: =VLOOKUP(J3, Sheet2!A:C, 2, FALSE) -> POHEGAON BK.
A4: Mr. | B4: Kale | C4: Bhaginath | D4: Karbhari | E4: Male | F4: 20607 | G4: 164 | H4: P.D. Commerce | I4: 1975 | J4: Kopargaon | K4: =VLOOKUP(J4, Sheet2!A:C, 3, FALSE) -> 423601 | L4: =VLOOKUP(J4, Sheet2!A:C, 2, FALSE) -> KOPARGAON
A5: Mr. | B5: Lowande | C5: Bhaskar | D5: Baburao | E5: Male | F5: 20111 | G5: 164 | H5: P.D. Commerce | I5: 1975 | J5: Shirdi | K5: =VLOOKUP(J5, Sheet2!A:C, 3, FALSE) -> 423109 | L5: =VLOOKUP(J5, Sheet2!A:C, 2, FALSE) -> SHIRDI
A6: Mr. | B6: Lute | C6: Dyaneshwar | D6: gopinath | E6: Male | F6: 21446 | G6: 164 | H6: P.D. Commerce | I6: 1975 | J6: Kopargaon | K6: =VLOOKUP(J6, Sheet2!A:C, 3, FALSE) -> 423601 | L6: =VLOOKUP(J6, Sheet2!A:C, 2, FALSE) -> KOPARGAON
A7: Miss. | B7: Lohade | C7: Sujata | D7: Santilal | E7: Female | F7: 21844 | G7: 164 | H7: P.D. Commerce | I7: 1975 | J7: Kopargaon | K7: =VLOOKUP(J7, Sheet2!A:C, 3, FALSE) -> 423601 | L7: =VLOOKUP(J7, Sheet2!A:C, 2, FALSE) -> KOPARGAON
A8: Mr. | B8: Lodha | C8: Sanchala | D8: Bhikchand | E8: Male | F8: 20713 | G8: 164 | H8: P.D. Commerce | I8: 1975 | J8: Shirdi | K8: =VLOOKUP(J8, Sheet2!A:C, 3, FALSE) -> 423109 | L8: =VLOOKUP(J8, Sheet2!A:C, 2, FALSE) -> SHIRDI
A9: Mr. | B9: Longani | C9: vinodkumar | D9: Ramlal | E9: Male | F9: 20953 | G9: 164 | H9: P.D. Commerce | I9: 1975 | J9: Kopargaon | K9: =VLOOKUP(J9, Sheet2!A:C, 3, FALSE) -> 423601 | L9: =VLOOKUP(J9, Sheet2!A:C, 2, FALSE) -> KOPARGAON
A10: Mr. | B10: Gayake | C10: Prakash | D10: Shankarrao | E10: Male | F10: 21277 | G10: 164 | H10: P.D. Commerce | I10: 1975 | J10: Shirdi | K10: =VLOOKUP(J10, Sheet2!A:C, 3, FALSE) -> 423109 | L10: =VLOOKUP(J10, Sheet2!A:C, 2, FALSE) -> SHIRDI
A11: Mr. | B11: Gorhe | C11: Nandkumar | D11: Ramchandra | E11: Male | F11: 21647 | G11: 164 | H11: P.D. Commerce | I11: 1975 | J11: Kopargaon | K11: =VLOOKUP(J11, Sheet2!A:C, 3, FALSE) -> 423601 | L11: =VLOOKUP(J11, Sheet2!A:C, 2, FALSE) -> KOPARGAON
A12: Mr. | B12: Gondkar | C12: Eknath | D12: Bhagwat | E12: Male | F12: 21833 | G12: 164 | H12: P.D. Commerce | I12: 1975 | J12: Shirdi | K12: =VLOOKUP(J12, Sheet2!A:C, 3, FALSE) -> 423109 | L12: =VLOOKUP(J12, Sheet2!A:C, 2, FALSE) -> SHIRDI
A13: Mr. | B13: Hon | C13: Sivaji | D13: Kalyanrao | E13: Male | F13: 21368 | G13: 164 | H13: P.D. Commerce | I13: 1975 | J13: Kopargaon | K13: =VLOOKUP(J13, Sheet2!A:C, 3, FALSE) -> 423601 | L13: =VLOOKUP(J13, Sheet2!A:C, 2, FALSE) -> KOPARGAON
A14: Mr. | B14: Hon | C14: Vinayak | D14: Doulatrao | E14: Male | F14: 20292 | G14: 164 | H14: P.D. Commerce | I14: 1975 | J14: Kopargaon | K14: =VLOOKUP(J14, Sheet2!A:C, 3, FALSE) -> 423601 | L14: =VLOOKUP(J14, Sheet2!A:C, 2, FALSE) -> KOPARGAON
... A16: Mr. | B16: Joshi | C16: Dattatrya | D16: Achyutrao | E16: Male | F16: 20417 | G16: 164 | H16: P.D. Commerce | I16: 1975 | J16: Kopargaon | K16: =VLOOKUP(J16, Sheet2!A:C, 3, FALSE) -> 423601 | L16: =VLOOKUP(J16, Sheet2!A:C, 2, FALSE) -> KOPARGAON
A17: Miss. | B17: Joshi | C17: Nanda | D17: Sitaram | E17: Female | F17: 21479 | G17: 163 | H17: P.D. Commerce | I17: 1975 | J17: Shirur | K17: 412210 | L17: SHIRUR
A18: Mr. | B18: Deshnabe | C18: Ashok | D18: Sitaram | E18: Male | F18: 20242 | G18: 164 | H18: P.D. Commerce | I18: 1975 | J18: Kopargaon | K18: 423601 | L18: KOPARGAON
A19: Mr. | B19: Dhage | C19: SunilKumar | D19: Madhavrao | E19: Male | F19: 20334 | G19: 164 | H19: P.D. Commerce | I19: 1975 | J19: Dhamni | K19: 423601 | L19: KOPARGAON
A20: Mr. | B20: Dusane | C20: Dinesh | D20: Jagannath | E20: Male | F20: 20111 | G20: 164 | H20: P.D. Commerce | I20: 1975 | J20: Kopargaon | K20: 423601 | L20: KOPARGAON
A21: Mr. | B21: Gade | C21: Prabhakar | D21: Sitaram | E21: Male | F21: 20242 | G21: 164 | H21: P.D. Commerce | I21: 1975 | J21: Kopargaon | K21: 423601 | L21: KOPARGAON
A22: Mr. | B22: Gade | C22: Vilas | D22: Bajirao | E22: Male | F22: 21844 | G22: 164 | H22: P.D. Commerce | I22: 1975 | J22: Kopargaon | K22: 423601 | L22: KOPARGAON
A23: Mr. | B23: Gavhane | C23: Jagganath | D23: Karbhari | E23: Male | F23: 20953 | G23: 164 | H23: P.D. Commerce | I23: 1975 | J23: Dorhale | K23: 423601 | L23: KOPARGAON
A24: Mr. | B24: Gade | C24: Hariram | D24: Hanumant | E24: Male | F24: 21002 | G24: 165 | H24: P.D. Commerce | I24: 1975 | J24: Chasnali | K24: 423601 | L24: KOPARGAON
A25: Mr. | B25: Bhangale | C25: Anil | D25: Tryambak | E25: Male | F25: 21011 | G25: 161 | H25: P.D. Commerce | I25: 1975 | J25: Kopargaon | K25: 423601 | L25: KOPARGAON
A26: Mr. | B26: bhair | C26: kiran | D26: Jalani | E26: Male | F26: 21119 | G26: 161 | H26: P.D. Commerce | I26: 1975 | J26: Kopargaon | K26: 423601 | L26: KOPARGAON
A27: Mr. | B27: Chandre | C27: Govardhan | D27: Changdeo | E27: Male | F27: 20828 | G27: 161 | H27: P.D. Commerce | I27: 1975 | J27: Malegaon | K27: 423203 | L27: MALEGAON
A28: Mr. | B28: Dabhale | C28: Bhausaheb | D28: keshev | E28: Male | F28: 21337 | G28: 161 | H28: P.D. Commerce | I28: 1975 | J28: Kopargaon | K28: 423601 | L28: KOPARGAON
... A33: Mr. | B33: Adhav | C33: Sopan | D33: Pandurang | E33: Male | F33: 20154 | G33: 159 | H33: P.D. Commerce | I33: 1975 | J33: Kopargaon | K33: 423601 | L33: KOPARGAON
A34: Mr. | B34: Bhaskar | C34: Ramesh | D34: Ganpatrao | F34: 19876 | G34: 159 | H34: P.D. Commerce | I34: 1975 | J34: Kopargaon | K34: 423601 | L34: KOPARGAON
A35: Mr. | B35: Bhansali | C35: Suresh | D35: Dipchand | F35: 20550 | G35: 159 | H35: P.D. Commerce | I35: 1975 | J35: Kopargaon | K35: 423601 | L35: KOPARGAON
A36: Miss. | B36: Bumb | C36: Latadevi | D36: Premchand | F36: 21378 | G36: 159 | H36: P.D. Commerce | I36: 1975 | J36: Kopargaon | K36: 423601 | L36: KOPARGAON
A37: Miss. | B37: Baviskar | C37: Asha | D37: Mahadeo | E37: Female | F37: 21277 | G37: 159 | H37: P.D. Commerce | I37: 1975 | J37: Kopargaon | K37: 423601 | L37: KOPARGAON
A38: Mr. | B38: Bhandari | C38: Premraj | D38: Rupchand | E38: Male | F38: 19818 | G38: 159 | H38: P.D. Commerce | I38: 1975 | J38: Yesgaon | K38: 422001 | L38: NASHIK
A39: Mr. | B39: Bapana | C39: Lalitkumar | D39: MishriLala | E39: Male | F39: 21550 | G39: 159 | H39: P.D. Commerce | I39: 1975 | J39: Kopargaon | K39: 423601 | L39: KOPARGAON
A40: Mr. | B40: Avhad | C40: Ashok | D40: Baburao | E40: Male | F40: 21250 | G40: 158 | H40: P.D. Commerce | I40: 1975 | J40: Kopargaon | K40: 423601 | L40: KOPARGAON
A41: Mr. | B41: Bagul | C41: Madhurkar | D41: Tulashiram | E41: Male | F41: 20154 | G41: 158 | H41: P.D. Commerce | I41: 1975 | J41: Kopargaon | K41: 423601 | L41: KOPARGAON
A42: Mr. | B42: Ukande | C42: Ravindra | D42: Girjapappa | E42: Male | F42: 20154 | G42: 158 | H42: P.D. Commerce | I42: 1975 | J42: Kopargaon | K42: 423601 | L42: KOPARGAON
A43: Mr. | B43: Lowande | C43: Bhaskar | D43: Baburao | E43: Male | F43: 20154 | G43: 158 | H43: P.D. Commerce | I43: 1975 | J43: Kopargaon | K43: 423601 | L43: KOPARGAON
A44: Mr. | B44: Deshpande | C44: Ashok | D44: Sitaram | E44: Male | F44: 19876 | G44: 158 | H44: P.D. Commerce | I44: 1975 | J44: Kopargaon | K44: 423601 | L44: KOPARGAON
A45: Mr. | B45: Abhale | C45: Pandharinath | D45: Muralidhar | E45: Male | F45: 20550 | G45: 158 | H45: P.D. Commerce | I45: 1975 | J45: Kopargaon | K45: 423601 | L45: KOPARGAON
A46: Mr. | B46: Abhale | C46: Sahebrao | D46: Gangadhar | E46: Male | F46: 21378 | G46: 158 | H46: P.D. Commerce | I46: 1975 | J46: Kopargaon | K46: 423601 | L46: KOPARGAON
...
